Workbook

Sheet Start Here
A1: Topic | B1: Details
A2: Project | B2: Multirotor Recovery Dynamics — calculations and simulation archive
A3: Source snapshot | B3: fbc4c878a99f68650c70670e7ee3721a6a24e67d
A4: Imported on | B4: 2026-09-28
A5: Scope | B5: All six committed simulation JSON files; engineering CSVs; component studies; equations, model source, plot sources and a reproduced release time series.
A6: Evidence | B6: Simulation outputs describe the historical design profile. They are not measurements of the Veeniix V995.
A7: V995 | B7: Owner-estimated mass around 50 g. Do not substitute the historical 135.66 g design budget for a measured V995 mass.
A8: Raw data | B8: Original JSON fields and CSV values are preserved. Nested objects become dotted columns. JSON arrays in metadata remain JSON text. Blank values remain unavailable, not zero.
A9: Live calculations | B9: Sizing, guard, mixer, statistics and research workbook formulas recalculate in Sheets. Imported simulation outputs are snapshots; editing inputs does not rerun Python dynamics.
A10: Scenarios | B10: Study A and A2 are release_startup. Scenario Trials holds the newer three-arm exploratory diagnostic. Do not pool these as equivalent experiments.
A11: Statistics | B11: Bounds describe Monte Carlo sampling uncertainty conditional on the model. Zero successes does not establish equivalence or physical impossibility.
A12: Historical policy | B12: Package Rankings preserves the source policy key as a historical package/configuration ranking, not a verified runtime switching policy.
... A16: Refresh | B16: Refresh source tables from a new pinned commit, then rebuild charts and recalculate. This workbook is a snapshot, not a live GitHub sync.

Sheet Charts
A1: Chart | B1: Meaning
A2: Release plots | B2: Reproduced nominal release trace; historical design and placeholder torque authority.
A3: Study plots | B3: Frozen touchdown proxy, not physical flight qualification.
A4: Diagnostic plots | B4: Limited exploratory prescribed-upset cohort; three scenario arms, 12 paired draws per cell/package/class.

Sheet Study Charts
A1: Exploratory survivable-set maps — release_startup | B1: One-sided 95% lower bounds by state cell. Frozen assumed touchdown proxy. Simulation only; not measured V995 performance.

Sheet Source Index
A1: Tab | B1: Source path | C1: Source URL | D1: Rows excluding header | E1: Notes
A2: Start Here | D2: 15
A3: Charts | D3: 3
A4: Mass Budget | B4: Engineering Data/mass_budget.csv | C4: https://github.com/500ft/multirotor-recovery-dynamics/blob/fbc4c878a99f68650c70670e7ee3721a6a24e67d/Engineering%20Data/mass_budget.csv | D4: 11 | E4: Imported without changing source evidence status.
A5: Power Budget | B5: Engineering Data/power_budget.csv | C5: https://github.com/500ft/multirotor-recovery-dynamics/blob/fbc4c878a99f68650c70670e7ee3721a6a24e67d/Engineering%20Data/power_budget.csv | D5: 4 | E5: Imported without changing source evidence status.
A6: Estimates | B6: Engineering Data/estimates.csv | C6: https://github.com/500ft/multirotor-recovery-dynamics/blob/fbc4c878a99f68650c70670e7ee3721a6a24e67d/Engineering%20Data/estimates.csv | D6: 23 | E6: Imported without changing source evidence status.
A7: Component Verification | B7: Engineering Data/component_verification.csv | C7: https://github.com/500ft/multirotor-recovery-dynamics/blob/fbc4c878a99f68650c70670e7ee3721a6a24e67d/Engineering%20Data/component_verification.csv | D7: 24 | E7: Imported without changing source evidence status.
A8: Hardware Interfaces | B8: Engineering Data/hardware_interfaces.csv | C8: https://github.com/500ft/multirotor-recovery-dynamics/blob/fbc4c878a99f68650c70670e7ee3721a6a24e67d/Engineering%20Data/hardware_interfaces.csv | D8: 13 | E8: Imported without changing source evidence status.
A9: Instrumentation | B9: Engineering Data/instrumentation.csv | C9: https://github.com/500ft/multirotor-recovery-dynamics/blob/fbc4c878a99f68650c70670e7ee3721a6a24e67d/Engineering%20Data/instrumentation.csv | D9: 11 | E9: Imported without changing source evidence status.
A10: Requirements | B10: Engineering Data/requirements.csv | C10: https://github.com/500ft/multirotor-recovery-dynamics/blob/fbc4c878a99f68650c70670e7ee3721a6a24e67d/Engineering%20Data/requirements.csv | D10: 17 | E10: Imported without changing source evidence status.
A11: BOM | B11: Design Report/BOM.csv | C11: https://github.com/500ft/multirotor-recovery-dynamics/blob/fbc4c878a99f68650c70670e7ee3721a6a24e67d/Design%20Report/BOM.csv | D11: 16 | E11: Imported without changing source evidence status.
A12: Purchase Checklist | B12: Engineering Data/purchase_checklist.csv | C12: https://github.com/500ft/multirotor-recovery-dynamics/blob/fbc4c878a99f68650c70670e7ee3721a6a24e67d/Engineering%20Data/purchase_checklist.csv | D12: 12 | E12: Imported without changing source evidence status.
A13: FMEA | B13: Engineering Data/fmea.csv | C13: https://github.com/500ft/multirotor-recovery-dynamics/blob/fbc4c878a99f68650c70670e7ee3721a6a24e67d/Engineering%20Data/fmea.csv | D13: 10 | E13: Imported without changing source evidence status.
A14: CAD Parameters | B14: cad/bench/parameters.csv | C14: https://github.com/500ft/multirotor-recovery-dynamics/blob/fbc4c878a99f68650c70670e7ee3721a6a24e67d/cad/bench/parameters.csv | D14: 26 | E14: Imported without changing source evidence status.
A15: CAD Input Requests | B15: cad/bench/input-requests.csv | C15: https://github.com/500ft/multirotor-recovery-dynamics/blob/fbc4c878a99f68650c70670e7ee3721a6a24e67d/cad/bench/input-requests.csv | D15: 12 | E15: Imported without changing source evidence status.
... A24: Paired A2 | B24: Data/survivable_set_results_a2.json | C24: https://github.com/500ft/multirotor-recovery-dynamics/blob/fbc4c878a99f68650c70670e7ee3721a6a24e67d/Data/survivable_set_results_a2.json | D24: 96 | E24: Paired mechanism versus reallocation. Null interval bounds remain blank.
A25: Package Rankings | B25: Data/survivable_set_results*.json | D25: 192 | E25: Source policy records; configuration ranking only.
A26: Primary Comparisons | B26: Data/survivable_set_results*.json | D26: 8 | E26: Historical kill-criterion outputs, not a non-inferiority test.
A27: Scenario Trials | B27: Data/scenario-diagnostic/scenario_diagnostic.json | C27: https://github.com/500ft/multirotor-recovery-dynamics/blob/fbc4c878a99f68650c70670e7ee3721a6a24e67d/Data/scenario-diagnostic/scenario_diagnostic.json | D27: 288 | E27: 288 exploratory trial endpoints; source pair indices are preserved. No measured V995 performance.
A28: Scenario Contrasts | B28: Data/scenario-diagnostic/scenario_diagnostic.json | C28: https://github.com/500ft/multirotor-recovery-dynamics/blob/fbc4c878a99f68650c70670e7ee3721a6a24e67d/Data/scenario-diagnostic/scenario_diagnostic.json | D28: 12 | E28: Conditional paired binary comparisons.
A29: Continuous Contrasts | B29: Data/scenario-diagnostic/scenario_diagnostic.json | C29: https://github.com/500ft/multirotor-recovery-dynamics/blob/fbc4c878a99f68650c70670e7ee3721a6a24e67d/Data/scenario-diagnostic/scenario_diagnostic.json | D29: 12 | E29: Paired differences; min/max are not confidence bounds.
A30: Convergence | B30: Data/survivable_set_convergence.json | C30: https://github.com/500ft/multirotor-recovery-dynamics/blob/fbc4c878a99f68650c70670e7ee3721a6a24e67d/Data/survivable_set_convergence.json | D30: 12 | E30: Historical dt diagnostic; does not establish model validity.
A31: Monte Carlo | B31: Data/monte_carlo_results.json | C31: https://github.com/500ft/multirotor-recovery-dynamics/blob/fbc4c878a99f68650c70670e7ee3721a6a24e67d/Data/monte_carlo_results.json | D31: 9 | E31: Committed summaries. Individual draws were not saved.
A32: Release Envelope | B32: Data/release_recovery_results.json | C32: https://github.com/500ft/multirotor-recovery-dynamics/blob/fbc4c878a99f68650c70670e7ee3721a6a24e67d/Data/release_recovery_results.json | D32: 3 | E32: Best-tier bound is sensor-limited, not a demonstrated dynamic failure boundary.
A33: Simulation Metadata | B33: Data/*.json | D33: 125 | E33: Source registration, assumptions, seeds, reported verdicts and runtime metadata.
A34: Recovery Envelope Model | B34: Analysis/recovery.py | C34: https://github.com/500ft/multirotor-recovery-dynamics/blob/fbc4c878a99f68650c70670e7ee3721a6a24e67d/Analysis/recovery.py | D34: 3 | E34: Recomputed first-order envelope. Historical defaults differ from current mass budget and 6-DoF model; intentionally preserved.
A35: Simulation Parameters | B35: Analysis/sim_release_recovery.py | C35: https://github.com/500ft/multirotor-recovery-dynamics/blob/fbc4c878a99f68650c70670e7ee3721a6a24e67d/Analysis/sim_release_recovery.py | D35: 3 | E35: Historical modeled parameters; not V995 measurements.
A36: Release Trace | B36: Analysis/sim_release_recovery.py | C36: https://github.com/500ft/multirotor-recovery-dynamics/blob/fbc4c878a99f68650c70670e7ee3721a6a24e67d/Analysis/sim_release_recovery.py | D36: 12000 | E36: REPRODUCED 2026-09-28. Full 12000 logged samples, dt=0.0005 s. World z positive upward; ground at -3 m. No downsampling.
A37: Sizing Calculations | B37: Analysis/budget.py; Design Report/calculations.md | D37: 23 | E37: Live formulas. Historical design only.
A38: Guard Calculations | B38: Analysis/guard.py | C38: https://github.com/500ft/multirotor-recovery-dynamics/blob/fbc4c878a99f68650c70670e7ee3721a6a24e67d/Analysis/guard.py | D38: 3 | E38: Assumed linear-elastic inputs. Does not establish fracture survival.
A39: Mixer Authority | B39: Analysis/sim_release_recovery.py | C39: https://github.com/500ft/multirotor-recovery-dynamics/blob/fbc4c878a99f68650c70670e7ee3721a6a24e67d/Analysis/sim_release_recovery.py | D39: 101 | E39: Four healthy symmetric rotors; assumed 60 mm arm. Not the rotor-out allocation solution.
A40: Statistics Calculations | B40: Analysis/classifier_stats.py; Analysis/monte_carlo_recovery.py | D40: 7 | E40: Illustrative live formulas. No Tango interval or non-inferiority claim added.
A41: CS Component Candidates | B41: Research/Component Study/Drone_Component_and_Propulsion_Study.xlsx#Component Candidates | D41: 45 | E41: Original component workbook; all 157 formulas retained with translated sheet references. Historical catalog assumptions.
A42: CS Reference Drones | B42: Research/Component Study/Drone_Component_and_Propulsion_Study.xlsx#Reference Drones | D42: 11 | E42: Original component workbook; all 157 formulas retained with translated sheet references. Historical catalog assumptions.
A43: CS Battery Architectures | B43: Research/Component Study/Drone_Component_and_Propulsion_Study.xlsx#Battery Architectures | D43: 10 | E43: Original component workbook; all 157 formulas retained with translated sheet references. Historical catalog assumptions.
A44: CS Propulsion Study | B44: Research/Component Study/Drone_Component_and_Propulsion_Study.xlsx#Propulsion Study | D44: 16 | E44: Original component workbook; all 157 formulas retained with translated sheet references. Historical catalog assumptions.
A45: CS Sources | B45: Research/Component Study/Drone_Component_and_Propulsion_Study.xlsx#Assumptions & Sources | D45: 20 | E45: Original component workbook; all 157 formulas retained with translated sheet references. Historical catalog assumptions.
A46: CS Dashboard | B46: Research/Component Study/Drone_Component_and_Propulsion_Study.xlsx#Dashboard | D46: 30 | E46: Original component workbook; all 157 formulas retained with translated sheet references. Historical catalog assumptions.
A47: CS Checks | B47: Research/Component Study/Drone_Component_and_Propulsion_Study.xlsx#Checks | D47: 10 | E47: Original component workbook; all 157 formulas retained with translated sheet references. Historical catalog assumptions.
A48: Component Selection | B48: Research/Component Study/component-selection-2026/Component_Selection_2026.xlsx | C48: https://github.com/500ft/multirotor-recovery-dynamics/blob/fbc4c878a99f68650c70670e7ee3721a6a24e67d/Research/Component%20Study/component-selection-2026/Component_Selection_2026.xlsx | D48: 209 | E48: Lossless nonempty-row archive of all 22 original tabs. Original headings retained as rows; source column letters map back to workbook.
...

Sheet Equation Register
A1: Calculation | B1: Equation or method | C1: Units | D1: Workbook location | E1: Implementation | F1: Limitations
A2: Mass freeze | B2: m_frozen = 5 ceil((sum(m_worst)+5)/5) | C2: g | D2: Sizing Calculations | E2: Analysis/budget.py | F2: 5 g allowance is selected, not measured
A3: Thrust requirement | B3: T_motor = (T/W) m / 4 | C3: gf with mass in g | D3: Sizing Calculations | E3: Analysis/gates.py | F3: Historical quadrotor sizing
A4: Flight time | B4: t_min = 60 C_Ah f_usable / I_A | C4: min | D4: Sizing Calculations | E4: Design Report/calculations.md | F4: Constant average current approximation
A5: Guard geometry | B5: D_inner=D_prop+2c; D_outer=D_inner+2t | C5: mm | D5: Sizing Calculations | E5: Design Report/calculations.md | F5: Clearance and wall are targets
A6: Angular arrest | B6: t = I |omega| / tau | C6: s | D6: Recovery Envelope Model | E6: Analysis/recovery.py | F6: Constant opposing torque
A7: Rest-to-rest rotation | B7: t = 2 sqrt(|theta| I / tau) | C7: s | D7: Recovery Envelope Model | E7: Analysis/recovery.py | F7: Bang-bang single-axis model
A8: Vertical envelope | B8: a_down = g - (T_up + 0.5 rho Cd A v_down^2)/m | C8: m/s² | D8: Recovery Envelope Model | E8: Analysis/recovery.py | F8: Downward-positive convention
A9: Rigid-body dynamics | B9: omega_dot = I^-1 (tau - omega cross (I omega)) | C9: rad/s² | D9: Model Functions | E9: Analysis/rigid_body.py | F9: Body angular rates, diagonal inertia
A10: Attitude kinematics | B10: q_dot = 0.5 q tensor (0,omega); normalize(q_next) | C10: 1/s | D10: Model Functions | E10: Analysis/rigid_body.py | F10: Quaternion w,x,y,z; body to world
A11: 6-DoF translation | B11: m v_dot = R(q)[0,0,T] + F_drag - [0,0,mg] | C11: N | D11: Model Functions | E11: Analysis/sim_release_recovery.py | F11: World z positive upward; see exact integrator
A12: Mixer differential | B12: d=max(0,min(T/4,T_max/4-T/4)) | C12: N | D12: Mixer Authority | E12: Analysis/sim_release_recovery.py | F12: Four healthy motors
... A27: Free fall | B27: d=0.5 g t^2; v=g t | C27: m, m/s | D27: Calculation Notes | E27: Design Report/calculations.md | F27: From rest, no drag

Sheet Sizing Calculations
A1: Quantity | B1: Value | C1: Unit | D1: Basis
A2: Best mass | B2: =SUM('Mass Budget'!C2:C12) -> 123.86 | C2: g | D2: Historical design budget
A3: Nominal mass | B3: =SUM('Mass Budget'!D2:D12) -> 135.66 | C3: g | D3: Historical design budget
A4: Worst mass | B4: =SUM('Mass Budget'!E2:E12) -> 156 | C4: g | D4: Historical design budget
A5: Unmodeled hardware | B5: 5 | C5: g | D5: Selected allowance; not itemized
A6: Proposed frozen maximum | B6: =CEILING(B4+B5,5) -> 165 | C6: g | D6: Analysis/budget.py
A7: Nominal margin | B7: =B6-B3 -> 29.34 | C7: g | D7: Frozen maximum minus nominal
A8: Abort threshold | B8: 225 | C8: g | D8: Selected design threshold; not a V995 limit
A9: Required thrust-to-weight | B9: 2 | C9: ratio | D9: REQ-PROP-001
A10: Number of motors | B10: 4 | C10: count | D10: Quadrotor
A11: Required per-motor thrust | B11: =B9*B6/B10 -> 82.5 | C11: gf | D11: At proposed frozen maximum
A12: Required total thrust | B12: =B9*B6/1000*9.81 -> 3.2373 | C12: N | D12: g=9.81 m/s²
A13: 5 V nominal sensor current | B13: =SUM('Power Budget'!C2:C5) -> 315 | C13: mA | D13: Listed 5 V loads only
A14: 5 V worst sensor current | B14: =SUM('Power Budget'!D2:D5) -> 620 | C14: mA | D14: Listed 5 V loads only
A15: 5 V nominal sensor power | B15: =5*B13/1000 -> 1.575 | C15: W | D15: Excludes motors and unlisted loads
A16: Battery capacity | B16: 0.55 | C16: Ah | D16: Historical 2S pack example
A17: Usable capacity fraction | B17: 0.8 | C17: fraction | D17: Sizing assumption
A18: Average flight current | B18: 9 | C18: A | D18: Illustrative assumption, not measured
A19: Estimated flight duration | B19: =60*B16*B17/B18 -> 2.9333333 | C19: min | D19: Capacity/current approximation
A20: Propeller diameter | B20: 50.8 | C20: mm | D20: Historical 2 inch example
A21: Radial clearance | B21: 2.5 | C21: mm | D21: Preliminary target
A22: Wall thickness | B22: 2 | C22: mm | D22: Preliminary target
A23: Guard inner diameter | B23: =B20+2*B21 -> 55.8 | C23: mm | D23: Geometry example
A24: Guard outer diameter | B24: =B23+2*B22 -> 59.8 | C24: mm | D24: Geometry example

Sheet Guard Calculations
A1: Case | B1: Impact energy J | C1: Stiffness N/m | D1: Stress per force Pa/N | E1: Clearance m | F1: Allowable stress Pa | G1: Deflection m | H1: Equivalent force N | I1: Impact stress Pa | J1: Clearance SF | K1: Stress SF | L1: Functional pass
A2: best | B2: 0.02 | C2: 1400 | D2: 150000 | E2: 0.003 | F2: 20000000 | G2: =SQRT(2*B2/C2) -> 0.0053452248 | H2: =SQRT(2*B2*C2) -> 7.4833148 | I2: =D2*H2 -> 1122497.2 | J2: =E2/G2 -> 0.56124861 | K2: =F2/I2 -> 17.817416 | L2: =AND(J2>=2,K2>=3) -> FALSE
A3: nominal | B3: 0.05 | C3: 900 | D3: 225000 | E3: 0.0025 | F3: 16000000 | G3: =SQRT(2*B3/C3) -> 0.010540926 | H3: =SQRT(2*B3*C3) -> 9.486833 | I3: =D3*H3 -> 2134537.4 | J3: =E3/G3 -> 0.23717082 | K3: =F3/I3 -> 7.4957693 | L3: =AND(J3>=2,K3>=3) -> FALSE
A4: worst | B4: 0.1 | C4: 500 | D4: 300000 | E4: 0.002 | F4: 12000000 | G4: =SQRT(2*B4/C4) -> 0.02 | H4: =SQRT(2*B4*C4) -> 10 | I4: =D4*H4 -> 3000000 | J4: =E4/G4 -> 0.1 | K4: =F4/I4 -> 4 | L4: =AND(J4>=2,K4>=3) -> FALSE

Sheet Mixer Authority
A1: Collective fraction | B1: Max total thrust N | C1: Arm m | D1: Collective thrust N | E1: Differential per motor N | F1: Roll-pitch authority Nm
A2: 0 | B2: 4.2 | C2: 0.06 | D2: =A2*B2 -> 0 | E2: =MAX(0,MIN(D2/4,B2/4-D2/4)) -> 0 | F2: =2*SQRT(2)*C2*E2 -> 0
A3: 0.01 | B3: 4.2 | C3: 0.06 | D3: =A3*B3 -> 0.042 | E3: =MAX(0,MIN(D3/4,B3/4-D3/4)) -> 0.0105 | F3: =2*SQRT(2)*C3*E3 -> 0.0017819091
A4: 0.02 | B4: 4.2 | C4: 0.06 | D4: =A4*B4 -> 0.084 | E4: =MAX(0,MIN(D4/4,B4/4-D4/4)) -> 0.021 | F4: =2*SQRT(2)*C4*E4 -> 0.0035638182
A5: 0.03 | B5: 4.2 | C5: 0.06 | D5: =A5*B5 -> 0.126 | E5: =MAX(0,MIN(D5/4,B5/4-D5/4)) -> 0.0315 | F5: =2*SQRT(2)*C5*E5 -> 0.0053457273
A6: 0.04 | B6: 4.2 | C6: 0.06 | D6: =A6*B6 -> 0.168 | E6: =MAX(0,MIN(D6/4,B6/4-D6/4)) -> 0.042 | F6: =2*SQRT(2)*C6*E6 -> 0.0071276364
A7: 0.05 | B7: 4.2 | C7: 0.06 | D7: =A7*B7 -> 0.21 | E7: =MAX(0,MIN(D7/4,B7/4-D7/4)) -> 0.0525 | F7: =2*SQRT(2)*C7*E7 -> 0.0089095454
A8: 0.06 | B8: 4.2 | C8: 0.06 | D8: =A8*B8 -> 0.252 | E8: =MAX(0,MIN(D8/4,B8/4-D8/4)) -> 0.063 | F8: =2*SQRT(2)*C8*E8 -> 0.010691455
A9: 0.07 | B9: 4.2 | C9: 0.06 | D9: =A9*B9 -> 0.294 | E9: =MAX(0,MIN(D9/4,B9/4-D9/4)) -> 0.0735 | F9: =2*SQRT(2)*C9*E9 -> 0.012473364
A10: 0.08 | B10: 4.2 | C10: 0.06 | D10: =A10*B10 -> 0.336 | E10: =MAX(0,MIN(D10/4,B10/4-D10/4)) -> 0.084 | F10: =2*SQRT(2)*C10*E10 -> 0.014255273
A11: 0.09 | B11: 4.2 | C11: 0.06 | D11: =A11*B11 -> 0.378 | E11: =MAX(0,MIN(D11/4,B11/4-D11/4)) -> 0.0945 | F11: =2*SQRT(2)*C11*E11 -> 0.016037182
A12: 0.1 | B12: 4.2 | C12: 0.06 | D12: =A12*B12 -> 0.42 | E12: =MAX(0,MIN(D12/4,B12/4-D12/4)) -> 0.105 | F12: =2*SQRT(2)*C12*E12 -> 0.017819091
A13: 0.11 | B13: 4.2 | C13: 0.06 | D13: =A13*B13 -> 0.462 | E13: =MAX(0,MIN(D13/4,B13/4-D13/4)) -> 0.1155 | F13: =2*SQRT(2)*C13*E13 -> 0.019601
... A102: 1 | B102: 4.2 | C102: 0.06 | D102: =A102*B102 -> 4.2 | E102: =MAX(0,MIN(D102/4,B102/4-D102/4)) -> 0 | F102: =2*SQRT(2)*C102*E102 -> 0

Sheet Statistics Calculations
A1: Calculation | B1: n | C1: Events or successes | D1: Confidence | E1: Result | F1: Interpretation
A2: Zero-event upper bound | B2: 300 | C2: 0 | D2: 0.95 | E2: =1-(1-D2)^(1/B2) -> 0.0099360819 | F2: Exact one-sided upper event-rate bound
A3: Zero-event upper bound | B3: 1000 | C3: 0 | D3: 0.95 | E3: =1-(1-D3)^(1/B3) -> 0.0029912495 | F3: Exact one-sided upper event-rate bound
A4: Required n at max rate 0.01 | C4: 0.01 | D4: 0.95 | E4: =CEILING(LN(1-D4)/LN(1-C4),1) -> 299 | F4: Zero observed events required
A5: Required n at max rate 0.003 | C5: 0.003 | D5: 0.95 | E5: =CEILING(LN(1-D5)/LN(1-C5),1) -> 998 | F5: Zero observed events required
A6: Success fraction | B6: 300 | C6: 0 | D6: 0.95 | E6: =C6/B6 -> 0 | F6: Example matching zero-success primary cells
A7: One-sided success lower | B7: 300 | C7: 0 | D7: 0.95 | E7: =IF(C7=0,0,_xlfn.BETA.INV(1-D7,C7,B7-C7+1)) -> 0 | F7: Clopper-Pearson; sampling uncertainty only
A8: One-sided success upper | B8: 300 | C8: 0 | D8: 0.95 | E8: =IF(C8=B8,1,_xlfn.BETA.INV(D8,C8+1,B8-C8)) -> 0.0099360819 | F8: Clopper-Pearson; each endpoint is one-sided 95%

Sheet Release Envelope
A1: tier | B1: max_recoverable_rate_rad_s | C1: max_recoverable_rate_deg_s | D1: envelope_edge | E1: max_torque_n_m | F1: max_thrust_n | G1: available_height_m
A2: best | B2: 34.5 | C2: 1976.7044 | D2: gyro_limit | E2: 0.006 | F2: 5 | G2: 3
A3: nominal | B3: 3.5 | C3: 200.53523 | D3: failure | E3: 0.004 | F3: 4.2 | G3: 3
A4: worst | B4: 1 | C4: 57.29578 | D4: failure | E4: 0.0025 | F4: 3.5 | G4: 3

Sheet Release Trace
A1: time_s | B1: tilt_rad | C1: body_rate_rad_s | D1: altitude_z_m | E1: vertical_velocity_m_s | F1: collective_thrust_N
A2: 0 | B2: 1.0471976 | C2: 2 | D2: 0 | E2: 0 | F2: 0
A3: 0.0005 | B3: 1.0479048 | C3: 2 | D3: -2.4525e-06 | E3: -0.004905 | F3: 0
A4: 0.001 | B4: 1.0486123 | C4: 2 | D4: -7.3574997e-06 | E4: -0.0098099993 | F4: 0
A5: 0.0015 | B5: 1.0493202 | C5: 2 | D5: -1.4714998e-05 | E5: -0.014714997 | F5: 0
A6: 0.002 | B6: 1.0500283 | C6: 2 | D6: -2.4524993e-05 | E6: -0.01961999 | F6: 0
A7: 0.0025 | B7: 1.0507367 | C7: 2 | D7: -3.6787483e-05 | E7: -0.02452498 | F7: 0
A8: 0.003 | B8: 1.0514454 | C8: 2 | D8: -5.1502464e-05 | E8: -0.029429963 | F8: 0
A9: 0.0035 | B9: 1.0521543 | C9: 2 | D9: -6.8669933e-05 | E9: -0.034334938 | F9: 0
A10: 0.004 | B10: 1.0528636 | C10: 2 | D10: -8.8289886e-05 | E10: -0.039239905 | F10: 0
A11: 0.0045 | B11: 1.0535731 | C11: 2 | D11: -0.00011036232 | E11: -0.044144861 | F11: 0
A12: 0.005 | B12: 1.0542829 | C12: 2 | D12: -0.00013488722 | E12: -0.049049806 | F12: 0
A13: 0.0055 | B13: 1.054993 | C13: 2 | D13: -0.00016186459 | E13: -0.053954738 | F13: 0
... A12001: 5.9995 | B12001: 0 | C12001: 1.6717092e-09 | D12001: -0.0015475137 | E12001: 0.0016352113 | F12001: 1.2727527

Sheet Monte Carlo
A1: scenario | B1: initial_rate_rad_s | C1: n | D1: successes | E1: success_rate | F1: success_rate_95_lower | G1: descent_p50_m | H1: descent_max_m
A2: as-toleranced_cg5mm | B2: 1 | C2: 75 | D2: 3 | E2: 0.04 | F2: 0.01098986 | G2: 0.56441365 | H2: 0.82285271
A3: as-toleranced_cg5mm | B3: 2 | C3: 150 | D3: 6 | E3: 0.04 | F3: 0.017560962 | G3: 1.1210407 | H3: 2.2155016
A4: as-toleranced_cg5mm | B4: 3 | C4: 75 | D4: 1 | E4: 0.013333333 | F4: 0.00068367678 | G4: 1.8372977 | H4: 1.8372977
A5: balance-controlled_cg1mm | B5: 1 | C5: 75 | D5: 45 | E5: 0.6 | F5: 0.49853621 | G5: 0.3544341 | H5: 1.0117193
A6: balance-controlled_cg1mm | B6: 2 | C6: 150 | D6: 115 | E6: 0.76666667 | F6: 0.702805 | G6: 0.8373164 | H6: 2.4058195
A7: balance-controlled_cg1mm | B7: 3 | C7: 75 | D7: 32 | E7: 0.42666667 | F7: 0.32962637 | G7: 2.2428553 | H7: 2.9710038
A8: as-toleranced_cg5mm_mixer-authority | B8: 1 | C8: 75 | D8: 75 | E8: 1 | F8: 0.96084411 | G8: 0.32101097 | H8: 0.54106116
A9: as-toleranced_cg5mm_mixer-authority | B9: 2 | C9: 150 | D9: 150 | E9: 1 | F9: 0.98022656 | G9: 0.38518251 | H9: 0.81609106
A10: as-toleranced_cg5mm_mixer-authority | B10: 3 | C10: 75 | D10: 75 | E10: 1 | F10: 0.96084411 | G10: 0.51810024 | H10: 1.0129521

Sheet Study A
A1: stage | B1: class | C1: cell | D1: action | E1: variant | F1: n | G1: successes | H1: p_safe | I1: p_safe_95_lower | J1: p_safe_95_upper | K1: sensitivity_successes.strict | L1: sensitivity_successes.lenient
A2: exploratory | B2: one_out | C2: h1.5_vz-1.5_w2_d0.11 | D2: mechanism | E2: a | F2: 30 | G2: 2 | H2: 0.066666667 | I2: 0.011975801 | J2: 0.19532604 | K2: 1 | L2: 2
A3: exploratory | B3: one_out | C3: h1.5_vz-1.5_w2_d0.11 | D3: parachute | E3: a | F3: 2000 | G3: 0 | H3: 0 | I3: 0 | J3: 0.0014967449 | K3: 0 | L3: 0
A4: exploratory | B4: one_out | C4: h1.5_vz-1.5_w2_d0.11 | D4: realloc_only | E4: a | F4: 30 | G4: 2 | H4: 0.066666667 | I4: 0.011975801 | J4: 0.19532604 | K4: 2 | L4: 5
A5: exploratory | B5: one_out | C5: h1.5_vz-1.5_w2_d0.3 | D5: mechanism | E5: a | F5: 300 | G5: 0 | H5: 0 | I5: 0 | J5: 0.0099360819 | K5: 0 | L5: 0
A6: exploratory | B6: one_out | C6: h1.5_vz-1.5_w2_d0.3 | D6: parachute | E6: a | F6: 2000 | G6: 0 | H6: 0 | I6: 0 | J6: 0.0014967449 | K6: 0 | L6: 0
A7: exploratory | B7: one_out | C7: h1.5_vz-1.5_w2_d0.3 | D7: realloc_only | E7: a | F7: 300 | G7: 0 | H7: 0 | I7: 0 | J7: 0.0099360819 | K7: 0 | L7: 0
A8: exploratory | B8: one_out | C8: h1.5_vz-1.5_w6_d0.11 | D8: mechanism | E8: a | F8: 30 | G8: 0 | H8: 0 | I8: 0 | J8: 0.095033853 | K8: 0 | L8: 0
A9: exploratory | B9: one_out | C9: h1.5_vz-1.5_w6_d0.11 | D9: parachute | E9: a | F9: 2000 | G9: 0 | H9: 0 | I9: 0 | J9: 0.0014967449 | K9: 0 | L9: 0
A10: exploratory | B10: one_out | C10: h1.5_vz-1.5_w6_d0.11 | D10: realloc_only | E10: a | F10: 30 | G10: 0 | H10: 0 | I10: 0 | J10: 0.095033853 | K10: 0 | L10: 0
A11: exploratory | B11: one_out | C11: h1.5_vz-1.5_w6_d0.3 | D11: mechanism | E11: a | F11: 30 | G11: 0 | H11: 0 | I11: 0 | J11: 0.095033853 | K11: 0 | L11: 0
A12: exploratory | B12: one_out | C12: h1.5_vz-1.5_w6_d0.3 | D12: parachute | E12: a | F12: 2000 | G12: 0 | H12: 0 | I12: 0 | J12: 0.0014967449 | K12: 0 | L12: 0
A13: exploratory | B13: one_out | C13: h1.5_vz-1.5_w6_d0.3 | D13: realloc_only | E13: a | F13: 30 | G13: 0 | H13: 0 | I13: 0 | J13: 0.095033853 | K13: 0 | L13: 0
... A297: primary | B297: two_adjacent | C297: h3_vz0_w6_d0.11 | D297: realloc_only | E297: a | F297: 300 | G297: 0 | H297: 0 | I297: 0 | J297: 0.0099360819 | K297: 0 | L297: 0

Sheet Study A2
A1: stage | B1: class | C1: cell | D1: action | E1: variant | F1: n | G1: successes | H1: p_safe | I1: p_safe_95_lower | J1: p_safe_95_upper | K1: sensitivity_successes.strict | L1: sensitivity_successes.lenient
A2: exploratory | B2: one_out | C2: h1.5_vz-1.5_w2_d0.11 | D2: mechanism | E2: a2 | F2: 30 | G2: 2 | H2: 0.066666667 | I2: 0.011975801 | J2: 0.19532604 | K2: 1 | L2: 2
A3: exploratory | B3: one_out | C3: h1.5_vz-1.5_w2_d0.11 | D3: parachute | E3: a2 | F3: 2000 | G3: 0 | H3: 0 | I3: 0 | J3: 0.0014967449 | K3: 0 | L3: 0
A4: exploratory | B4: one_out | C4: h1.5_vz-1.5_w2_d0.11 | D4: realloc_only | E4: a2 | F4: 30 | G4: 2 | H4: 0.066666667 | I4: 0.011975801 | J4: 0.19532604 | K4: 2 | L4: 5
A5: exploratory | B5: one_out | C5: h1.5_vz-1.5_w2_d0.3 | D5: mechanism | E5: a2 | F5: 300 | G5: 0 | H5: 0 | I5: 0 | J5: 0.0099360819 | K5: 0 | L5: 0
A6: exploratory | B6: one_out | C6: h1.5_vz-1.5_w2_d0.3 | D6: parachute | E6: a2 | F6: 2000 | G6: 0 | H6: 0 | I6: 0 | J6: 0.0014967449 | K6: 0 | L6: 0
A7: exploratory | B7: one_out | C7: h1.5_vz-1.5_w2_d0.3 | D7: realloc_only | E7: a2 | F7: 300 | G7: 0 | H7: 0 | I7: 0 | J7: 0.0099360819 | K7: 0 | L7: 0
A8: exploratory | B8: one_out | C8: h1.5_vz-1.5_w6_d0.11 | D8: mechanism | E8: a2 | F8: 30 | G8: 0 | H8: 0 | I8: 0 | J8: 0.095033853 | K8: 0 | L8: 0
A9: exploratory | B9: one_out | C9: h1.5_vz-1.5_w6_d0.11 | D9: parachute | E9: a2 | F9: 2000 | G9: 0 | H9: 0 | I9: 0 | J9: 0.0014967449 | K9: 0 | L9: 0
A10: exploratory | B10: one_out | C10: h1.5_vz-1.5_w6_d0.11 | D10: realloc_only | E10: a2 | F10: 30 | G10: 0 | H10: 0 | I10: 0 | J10: 0.095033853 | K10: 0 | L10: 0
A11: exploratory | B11: one_out | C11: h1.5_vz-1.5_w6_d0.3 | D11: mechanism | E11: a2 | F11: 30 | G11: 0 | H11: 0 | I11: 0 | J11: 0.095033853 | K11: 0 | L11: 0
A12: exploratory | B12: one_out | C12: h1.5_vz-1.5_w6_d0.3 | D12: parachute | E12: a2 | F12: 2000 | G12: 0 | H12: 0 | I12: 0 | J12: 0.0014967449 | K12: 0 | L12: 0
A13: exploratory | B13: one_out | C13: h1.5_vz-1.5_w6_d0.3 | D13: realloc_only | E13: a2 | F13: 30 | G13: 0 | H13: 0 | I13: 0 | J13: 0.095033853 | K13: 0 | L13: 0
... A297: primary | B297: two_adjacent | C297: h3_vz0_w6_d0.11 | D297: realloc_only | E297: a2 | F297: 300 | G297: 0 | H297: 0 | I297: 0 | J297: 0.0099360819 | K297: 0 | L297: 0

Sheet Scenario Trials
A1: status | B1: safe | C1: impact_speed_m_s | D1: impact_tilt_rad | E1: t_contact_s | F1: t_switch_s | G1: max_descent_m | H1: class | I1: cell | J1: package | K1: arm | L1: pair
A2: contact | B2: FALSE | C2: 7.3989937 | D2: 1.0658969 | E2: 0.7795 | F2: 0.162 | G2: 2.9997407 | H2: one_out | I2: h3_vz0_w6_d0.11 | J2: mechanism | K2: release_startup | L2: 0
A3: contact | B3: FALSE | C3: 7.5884774 | D3: 0.74591488 | E3: 0.792 | F3: 0.162 | G3: 2.9993612 | H3: one_out | I3: h3_vz0_w6_d0.11 | J3: mechanism | K3: in_flight_hold_matched | L3: 0
A4: contact | B4: FALSE | C4: 7.8708608 | D4: 1.7693926 | E4: 0.8155 | F4: 0.11 | G4: 2.9985799 | H4: one_out | I4: h3_vz0_w6_d0.11 | J4: mechanism | K4: in_flight_hold_immediate | L4: 0
A5: contact | B5: FALSE | C5: 8.0215939 | D5: 2.5404958 | E5: 0.7795 | F5: 0.1665 | G5: 2.9980874 | H5: one_out | I5: h3_vz0_w6_d0.11 | J5: mechanism | K5: release_startup | L5: 1
A6: contact | B6: FALSE | C6: 6.1030075 | D6: 2.3949693 | E6: 0.8665 | F6: 0.1665 | G6: 2.9977588 | H6: one_out | I6: h3_vz0_w6_d0.11 | J6: mechanism | K6: in_flight_hold_matched | L6: 1
A7: contact | B7: FALSE | C7: 4.9194318 | D7: 0.63416922 | E7: 0.85 | F7: 0.11 | G7: 2.9983909 | H7: one_out | I7: h3_vz0_w6_d0.11 | J7: mechanism | K7: in_flight_hold_immediate | L7: 1
A8: contact | B8: FALSE | C8: 6.839334 | D8: 0.53276808 | E8: 0.7645 | F8: 0.1655 | G8: 2.9995193 | H8: one_out | I8: h3_vz0_w6_d0.11 | J8: mechanism | K8: release_startup | L8: 2
A9: contact | B9: FALSE | C9: 6.8633035 | D9: 0.23304644 | E9: 0.787 | F9: 0.1655 | G9: 2.9986026 | H9: one_out | I9: h3_vz0_w6_d0.11 | J9: mechanism | K9: in_flight_hold_matched | L9: 2
A10: contact | B10: FALSE | C10: 7.6740837 | D10: 1.2996089 | E10: 0.7975 | F10: 0.11 | G10: 2.9976761 | H10: one_out | I10: h3_vz0_w6_d0.11 | J10: mechanism | K10: in_flight_hold_immediate | L10: 2
A11: contact | B11: FALSE | C11: 7.9782295 | D11: 2.750325 | E11: 0.779 | F11: 0.192 | G11: 2.9991177 | H11: one_out | I11: h3_vz0_w6_d0.11 | J11: mechanism | K11: release_startup | L11: 3
A12: contact | B12: FALSE | C12: 4.5542475 | D12: 1.1173716 | E12: 0.8875 | F12: 0.192 | G12: 2.9986853 | H12: one_out | I12: h3_vz0_w6_d0.11 | J12: mechanism | K12: in_flight_hold_matched | L12: 3
A13: contact | B13: FALSE | C13: 7.3635372 | D13: 1.1262083 | E13: 0.816 | F13: 0.11 | G13: 2.9994363 | H13: one_out | I13: h3_vz0_w6_d0.11 | J13: mechanism | K13: in_flight_hold_immediate | L13: 3
... A289: contact | B289: FALSE | C289: 5.1848215 | D289: 2.5595009 | E289: 0.457 | F289: 0.3 | G289: 1.4977236 | H289: two_adjacent | I289: h1.5_vz-1.5_w2_d0.3 | J289: realloc_only | K289: in_flight_hold_immediate | L289: 11

Sheet Scenario Summary
A1: failure_class | B1: cell | C1: package | D1: arm | E1: n | F1: safe_count | G1: mean_impact_speed_m_s | H1: mean_contact_time_s
A2: one_out | B2: h1.5_vz-1.5_w2_d0.3 | C2: mechanism | D2: in_flight_hold_immediate | E2: =COUNTIFS('Scenario Trials'!$H$2:$H$289,$A2,'Scenario Trials'!$I$2:$I$289,$B2,'Scenario Trials'!$J$2:$J$289,$C2,'Scenario Trials'!$K$2:$K$289,$D2) -> 12 | F2: =COUNTIFS('Scenario Trials'!$H$2:$H$289,$A2,'Scenario Trials'!$I$2:$I$289,$B2,'Scenario Trials'!$J$2:$J$289,$C2,'Scenario Trials'!$K$2:$K$289,$D2,'Scenario Trials'!$B$2:$B$289,TRUE) -> 0 | G2: =AVERAGEIFS('Scenario Trials'!$C$2:$C$289,'Scenario Trials'!$H$2:$H$289,$A2,'Scenario Trials'!$I$2:$I$289,$B2,'Scenario Trials'!$J$2:$J$289,$C2,'Scenario Trials'!$K$2:$K$289,$D2) -> 5.4080845 | H2: =AVERAGEIFS('Scenario Trials'!$E$2:$E$289,'Scenario Trials'!$H$2:$H$289,$A2,'Scenario Trials'!$I$2:$I$289,$B2,'Scenario Trials'!$J$2:$J$289,$C2,'Scenario Trials'!$K$2:$K$289,$D2) -> 0.46416667
A3: one_out | B3: h1.5_vz-1.5_w2_d0.3 | C3: mechanism | D3: in_flight_hold_matched | E3: =COUNTIFS('Scenario Trials'!$H$2:$H$289,$A3,'Scenario Trials'!$I$2:$I$289,$B3,'Scenario Trials'!$J$2:$J$289,$C3,'Scenario Trials'!$K$2:$K$289,$D3) -> 12 | F3: =COUNTIFS('Scenario Trials'!$H$2:$H$289,$A3,'Scenario Trials'!$I$2:$I$289,$B3,'Scenario Trials'!$J$2:$J$289,$C3,'Scenario Trials'!$K$2:$K$289,$D3,'Scenario Trials'!$B$2:$B$289,TRUE) -> 0 | G3: =AVERAGEIFS('Scenario Trials'!$C$2:$C$289,'Scenario Trials'!$H$2:$H$289,$A3,'Scenario Trials'!$I$2:$I$289,$B3,'Scenario Trials'!$J$2:$J$289,$C3,'Scenario Trials'!$K$2:$K$289,$D3) -> 4.9681307 | H3: =AVERAGEIFS('Scenario Trials'!$E$2:$E$289,'Scenario Trials'!$H$2:$H$289,$A3,'Scenario Trials'!$I$2:$I$289,$B3,'Scenario Trials'!$J$2:$J$289,$C3,'Scenario Trials'!$K$2:$K$289,$D3) -> 0.473125
A4: one_out | B4: h1.5_vz-1.5_w2_d0.3 | C4: mechanism | D4: release_startup | E4: =COUNTIFS('Scenario Trials'!$H$2:$H$289,$A4,'Scenario Trials'!$I$2:$I$289,$B4,'Scenario Trials'!$J$2:$J$289,$C4,'Scenario Trials'!$K$2:$K$289,$D4) -> 12 | F4: =COUNTIFS('Scenario Trials'!$H$2:$H$289,$A4,'Scenario Trials'!$I$2:$I$289,$B4,'Scenario Trials'!$J$2:$J$289,$C4,'Scenario Trials'!$K$2:$K$289,$D4,'Scenario Trials'!$B$2:$B$289,TRUE) -> 0 | G4: =AVERAGEIFS('Scenario Trials'!$C$2:$C$289,'Scenario Trials'!$H$2:$H$289,$A4,'Scenario Trials'!$I$2:$I$289,$B4,'Scenario Trials'!$J$2:$J$289,$C4,'Scenario Trials'!$K$2:$K$289,$D4) -> 4.9162082 | H4: =AVERAGEIFS('Scenario Trials'!$E$2:$E$289,'Scenario Trials'!$H$2:$H$289,$A4,'Scenario Trials'!$I$2:$I$289,$B4,'Scenario Trials'!$J$2:$J$289,$C4,'Scenario Trials'!$K$2:$K$289,$D4) -> 0.43175
A5: one_out | B5: h1.5_vz-1.5_w2_d0.3 | C5: realloc_only | D5: in_flight_hold_immediate | E5: =COUNTIFS('Scenario Trials'!$H$2:$H$289,$A5,'Scenario Trials'!$I$2:$I$289,$B5,'Scenario Trials'!$J$2:$J$289,$C5,'Scenario Trials'!$K$2:$K$289,$D5) -> 12 | F5: =COUNTIFS('Scenario Trials'!$H$2:$H$289,$A5,'Scenario Trials'!$I$2:$I$289,$B5,'Scenario Trials'!$J$2:$J$289,$C5,'Scenario Trials'!$K$2:$K$289,$D5,'Scenario Trials'!$B$2:$B$289,TRUE) -> 0 | G5: =AVERAGEIFS('Scenario Trials'!$C$2:$C$289,'Scenario Trials'!$H$2:$H$289,$A5,'Scenario Trials'!$I$2:$I$289,$B5,'Scenario Trials'!$J$2:$J$289,$C5,'Scenario Trials'!$K$2:$K$289,$D5) -> 4.7608316 | H5: =AVERAGEIFS('Scenario Trials'!$E$2:$E$289,'Scenario Trials'!$H$2:$H$289,$A5,'Scenario Trials'!$I$2:$I$289,$B5,'Scenario Trials'!$J$2:$J$289,$C5,'Scenario Trials'!$K$2:$K$289,$D5) -> 0.47183333
A6: one_out | B6: h1.5_vz-1.5_w2_d0.3 | C6: realloc_only | D6: in_flight_hold_matched | E6: =COUNTIFS('Scenario Trials'!$H$2:$H$289,$A6,'Scenario Trials'!$I$2:$I$289,$B6,'Scenario Trials'!$J$2:$J$289,$C6,'Scenario Trials'!$K$2:$K$289,$D6) -> 12 | F6: =COUNTIFS('Scenario Trials'!$H$2:$H$289,$A6,'Scenario Trials'!$I$2:$I$289,$B6,'Scenario Trials'!$J$2:$J$289,$C6,'Scenario Trials'!$K$2:$K$289,$D6,'Scenario Trials'!$B$2:$B$289,TRUE) -> 0 | G6: =AVERAGEIFS('Scenario Trials'!$C$2:$C$289,'Scenario Trials'!$H$2:$H$289,$A6,'Scenario Trials'!$I$2:$I$289,$B6,'Scenario Trials'!$J$2:$J$289,$C6,'Scenario Trials'!$K$2:$K$289,$D6) -> 4.8807339 | H6: =AVERAGEIFS('Scenario Trials'!$E$2:$E$289,'Scenario Trials'!$H$2:$H$289,$A6,'Scenario Trials'!$I$2:$I$289,$B6,'Scenario Trials'!$J$2:$J$289,$C6,'Scenario Trials'!$K$2:$K$289,$D6) -> 0.47383333
A7: one_out | B7: h1.5_vz-1.5_w2_d0.3 | C7: realloc_only | D7: release_startup | E7: =COUNTIFS('Scenario Trials'!$H$2:$H$289,$A7,'Scenario Trials'!$I$2:$I$289,$B7,'Scenario Trials'!$J$2:$J$289,$C7,'Scenario Trials'!$K$2:$K$289,$D7) -> 12 | F7: =COUNTIFS('Scenario Trials'!$H$2:$H$289,$A7,'Scenario Trials'!$I$2:$I$289,$B7,'Scenario Trials'!$J$2:$J$289,$C7,'Scenario Trials'!$K$2:$K$289,$D7,'Scenario Trials'!$B$2:$B$289,TRUE) -> 0 | G7: =AVERAGEIFS('Scenario Trials'!$C$2:$C$289,'Scenario Trials'!$H$2:$H$289,$A7,'Scenario Trials'!$I$2:$I$289,$B7,'Scenario Trials'!$J$2:$J$289,$C7,'Scenario Trials'!$K$2:$K$289,$D7) -> 4.8251283 | H7: =AVERAGEIFS('Scenario Trials'!$E$2:$E$289,'Scenario Trials'!$H$2:$H$289,$A7,'Scenario Trials'!$I$2:$I$289,$B7,'Scenario Trials'!$J$2:$J$289,$C7,'Scenario Trials'!$K$2:$K$289,$D7) -> 0.433375
A8: one_out | B8: h3_vz0_w6_d0.11 | C8: mechanism | D8: in_flight_hold_immediate | E8: =COUNTIFS('Scenario Trials'!$H$2:$H$289,$A8,'Scenario Trials'!$I$2:$I$289,$B8,'Scenario Trials'!$J$2:$J$289,$C8,'Scenario Trials'!$K$2:$K$289,$D8) -> 12 | F8: =COUNTIFS('Scenario Trials'!$H$2:$H$289,$A8,'Scenario Trials'!$I$2:$I$289,$B8,'Scenario Trials'!$J$2:$J$289,$C8,'Scenario Trials'!$K$2:$K$289,$D8,'Scenario Trials'!$B$2:$B$289,TRUE) -> 0 | G8: =AVERAGEIFS('Scenario Trials'!$C$2:$C$289,'Scenario Trials'!$H$2:$H$289,$A8,'Scenario Trials'!$I$2:$I$289,$B8,'Scenario Trials'!$J$2:$J$289,$C8,'Scenario Trials'!$K$2:$K$289,$D8) -> 7.0259008 | H8: =AVERAGEIFS('Scenario Trials'!$E$2:$E$289,'Scenario Trials'!$H$2:$H$289,$A8,'Scenario Trials'!$I$2:$I$289,$B8,'Scenario Trials'!$J$2:$J$289,$C8,'Scenario Trials'!$K$2:$K$289,$D8) -> 0.81345833
A9: one_out | B9: h3_vz0_w6_d0.11 | C9: mechanism | D9: in_flight_hold_matched | E9: =COUNTIFS('Scenario Trials'!$H$2:$H$289,$A9,'Scenario Trials'!$I$2:$I$289,$B9,'Scenario Trials'!$J$2:$J$289,$C9,'Scenario Trials'!$K$2:$K$289,$D9) -> 12 | F9: =COUNTIFS('Scenario Trials'!$H$2:$H$289,$A9,'Scenario Trials'!$I$2:$I$289,$B9,'Scenario Trials'!$J$2:$J$289,$C9,'Scenario Trials'!$K$2:$K$289,$D9,'Scenario Trials'!$B$2:$B$289,TRUE) -> 0 | G9: =AVERAGEIFS('Scenario Trials'!$C$2:$C$289,'Scenario Trials'!$H$2:$H$289,$A9,'Scenario Trials'!$I$2:$I$289,$B9,'Scenario Trials'!$J$2:$J$289,$C9,'Scenario Trials'!$K$2:$K$289,$D9) -> 6.8009062 | H9: =AVERAGEIFS('Scenario Trials'!$E$2:$E$289,'Scenario Trials'!$H$2:$H$289,$A9,'Scenario Trials'!$I$2:$I$289,$B9,'Scenario Trials'!$J$2:$J$289,$C9,'Scenario Trials'!$K$2:$K$289,$D9) -> 0.81716667
A10: one_out | B10: h3_vz0_w6_d0.11 | C10: mechanism | D10: release_startup | E10: =COUNTIFS('Scenario Trials'!$H$2:$H$289,$A10,'Scenario Trials'!$I$2:$I$289,$B10,'Scenario Trials'!$J$2:$J$289,$C10,'Scenario Trials'!$K$2:$K$289,$D10) -> 12 | F10: =COUNTIFS('Scenario Trials'!$H$2:$H$289,$A10,'Scenario Trials'!$I$2:$I$289,$B10,'Scenario Trials'!$J$2:$J$289,$C10,'Scenario Trials'!$K$2:$K$289,$D10,'Scenario Trials'!$B$2:$B$289,TRUE) -> 0 | G10: =AVERAGEIFS('Scenario Trials'!$C$2:$C$289,'Scenario Trials'!$H$2:$H$289,$A10,'Scenario Trials'!$I$2:$I$289,$B10,'Scenario Trials'!$J$2:$J$289,$C10,'Scenario Trials'!$K$2:$K$289,$D10) -> 7.345775 | H10: =AVERAGEIFS('Scenario Trials'!$E$2:$E$289,'Scenario Trials'!$H$2:$H$289,$A10,'Scenario Trials'!$I$2:$I$289,$B10,'Scenario Trials'!$J$2:$J$289,$C10,'Scenario Trials'!$K$2:$K$289,$D10) -> 0.7645
A11: one_out | B11: h3_vz0_w6_d0.11 | C11: realloc_only | D11: in_flight_hold_immediate | E11: =COUNTIFS('Scenario Trials'!$H$2:$H$289,$A11,'Scenario Trials'!$I$2:$I$289,$B11,'Scenario Trials'!$J$2:$J$289,$C11,'Scenario Trials'!$K$2:$K$289,$D11) -> 12 | F11: =COUNTIFS('Scenario Trials'!$H$2:$H$289,$A11,'Scenario Trials'!$I$2:$I$289,$B11,'Scenario Trials'!$J$2:$J$289,$C11,'Scenario Trials'!$K$2:$K$289,$D11,'Scenario Trials'!$B$2:$B$289,TRUE) -> 0 | G11: =AVERAGEIFS('Scenario Trials'!$C$2:$C$289,'Scenario Trials'!$H$2:$H$289,$A11,'Scenario Trials'!$I$2:$I$289,$B11,'Scenario Trials'!$J$2:$J$289,$C11,'Scenario Trials'!$K$2:$K$289,$D11) -> 6.1661669 | H11: =AVERAGEIFS('Scenario Trials'!$E$2:$E$289,'Scenario Trials'!$H$2:$H$289,$A11,'Scenario Trials'!$I$2:$I$289,$B11,'Scenario Trials'!$J$2:$J$289,$C11,'Scenario Trials'!$K$2:$K$289,$D11) -> 0.90283333
A12: one_out | B12: h3_vz0_w6_d0.11 | C12: realloc_only | D12: in_flight_hold_matched | E12: =COUNTIFS('Scenario Trials'!$H$2:$H$289,$A12,'Scenario Trials'!$I$2:$I$289,$B12,'Scenario Trials'!$J$2:$J$289,$C12,'Scenario Trials'!$K$2:$K$289,$D12) -> 12 | F12: =COUNTIFS('Scenario Trials'!$H$2:$H$289,$A12,'Scenario Trials'!$I$2:$I$289,$B12,'Scenario Trials'!$J$2:$J$289,$C12,'Scenario Trials'!$K$2:$K$289,$D12,'Scenario Trials'!$B$2:$B$289,TRUE) -> 0 | G12: =AVERAGEIFS('Scenario Trials'!$C$2:$C$289,'Scenario Trials'!$H$2:$H$289,$A12,'Scenario Trials'!$I$2:$I$289,$B12,'Scenario Trials'!$J$2:$J$289,$C12,'Scenario Trials'!$K$2:$K$289,$D12) -> 6.5653095 | H12: =AVERAGEIFS('Scenario Trials'!$E$2:$E$289,'Scenario Trials'!$H$2:$H$289,$A12,'Scenario Trials'!$I$2:$I$289,$B12,'Scenario Trials'!$J$2:$J$289,$C12,'Scenario Trials'!$K$2:$K$289,$D12) -> 0.84483333
A13: one_out | B13: h3_vz0_w6_d0.11 | C13: realloc_only | D13: release_startup | E13: =COUNTIFS('Scenario Trials'!$H$2:$H$289,$A13,'Scenario Trials'!$I$2:$I$289,$B13,'Scenario Trials'!$J$2:$J$289,$C13,'Scenario Trials'!$K$2:$K$289,$D13) -> 12 | F13: =COUNTIFS('Scenario Trials'!$H$2:$H$289,$A13,'Scenario Trials'!$I$2:$I$289,$B13,'Scenario Trials'!$J$2:$J$289,$C13,'Scenario Trials'!$K$2:$K$289,$D13,'Scenario Trials'!$B$2:$B$289,TRUE) -> 0 | G13: =AVERAGEIFS('Scenario Trials'!$C$2:$C$289,'Scenario Trials'!$H$2:$H$289,$A13,'Scenario Trials'!$I$2:$I$289,$B13,'Scenario Trials'!$J$2:$J$289,$C13,'Scenario Trials'!$K$2:$K$289,$D13) -> 6.6142245 | H13: =AVERAGEIFS('Scenario Trials'!$E$2:$E$289,'Scenario Trials'!$H$2:$H$289,$A13,'Scenario Trials'!$I$2:$I$289,$B13,'Scenario Trials'!$J$2:$J$289,$C13,'Scenario Trials'!$K$2:$K$289,$D13) -> 0.81283333
... A25: two_adjacent | B25: h3_vz0_w6_d0.11 | C25: realloc_only | D25: release_startup | E25: =COUNTIFS('Scenario Trials'!$H$2:$H$289,$A25,'Scenario Trials'!$I$2:$I$289,$B25,'Scenario Trials'!$J$2:$J$289,$C25,'Scenario Trials'!$K$2:$K$289,$D25) -> 12 | F25: =COUNTIFS('Scenario Trials'!$H$2:$H$289,$A25,'Scenario Trials'!$I$2:$I$289,$B25,'Scenario Trials'!$J$2:$J$289,$C25,'Scenario Trials'!$K$2:$K$289,$D25,'Scenario Trials'!$B$2:$B$289,TRUE) -> 0 | G25: =AVERAGEIFS('Scenario Trials'!$C$2:$C$289,'Scenario Trials'!$H$2:$H$289,$A25,'Scenario Trials'!$I$2:$I$289,$B25,'Scenario Trials'!$J$2:$J$289,$C25,'Scenario Trials'!$K$2:$K$289,$D25) -> 6.5871316 | H25: =AVERAGEIFS('Scenario Trials'!$E$2:$E$289,'Scenario Trials'!$H$2:$H$289,$A25,'Scenario Trials'!$I$2:$I$289,$B25,'Scenario Trials'!$J$2:$J$289,$C25,'Scenario Trials'!$K$2:$K$289,$D25) -> 0.81825

Sheet Scenario Contrasts
A1: contrast | B1: class | C1: package | D1: n | E1: only_a | F1: only_b | G1: both | H1: neither | I1: delta | J1: midp
A2: H-L | B2: one_out | C2: mechanism | D2: 24 | E2: 0 | F2: 0 | G2: 0 | H2: 24 | I2: 0 | J2: 1
A3: H-L | B3: one_out | C3: realloc_only | D3: 24 | E3: 0 | F3: 0 | G3: 0 | H3: 24 | I3: 0 | J3: 1
A4: H-L | B4: two_adjacent | C4: mechanism | D4: 24 | E4: 0 | F4: 0 | G4: 0 | H4: 24 | I4: 0 | J4: 1
A5: H-L | B5: two_adjacent | C5: realloc_only | D5: 24 | E5: 0 | F5: 0 | G5: 0 | H5: 24 | I5: 0 | J5: 1
A6: I-H | B6: one_out | C6: mechanism | D6: 24 | E6: 0 | F6: 0 | G6: 0 | H6: 24 | I6: 0 | J6: 1
A7: I-H | B7: one_out | C7: realloc_only | D7: 24 | E7: 0 | F7: 0 | G7: 0 | H7: 24 | I7: 0 | J7: 1
A8: I-H | B8: two_adjacent | C8: mechanism | D8: 24 | E8: 0 | F8: 0 | G8: 0 | H8: 24 | I8: 0 | J8: 1
A9: I-H | B9: two_adjacent | C9: realloc_only | D9: 24 | E9: 0 | F9: 0 | G9: 0 | H9: 24 | I9: 0 | J9: 1
A10: I-L | B10: one_out | C10: mechanism | D10: 24 | E10: 0 | F10: 0 | G10: 0 | H10: 24 | I10: 0 | J10: 1
A11: I-L | B11: one_out | C11: realloc_only | D11: 24 | E11: 0 | F11: 0 | G11: 0 | H11: 24 | I11: 0 | J11: 1
A12: I-L | B12: two_adjacent | C12: mechanism | D12: 24 | E12: 0 | F12: 0 | G12: 0 | H12: 24 | I12: 0 | J12: 1
A13: I-L | B13: two_adjacent | C13: realloc_only | D13: 24 | E13: 0 | F13: 0 | G13: 0 | H13: 24 | I13: 0 | J13: 1

Sheet Continuous Contrasts
A1: contrast | B1: class | C1: cell | D1: n | E1: mean_d_impact_speed_m_s | F1: min_d_impact_speed_m_s | G1: max_d_impact_speed_m_s | H1: mean_d_time_to_contact_s
A2: H-L | B2: one_out | C2: h1.5_vz-1.5_w2_d0.3 | D2: 24 | E2: 0.053764071 | F2: -0.50322085 | G2: 1.0280412 | H2: 0.040916667
A3: H-L | B3: one_out | C3: h3_vz0_w6_d0.11 | D3: 24 | E3: -0.29689195 | F3: -3.423982 | G3: 0.7952798 | H3: 0.042333333
A4: H-L | B4: two_adjacent | C4: h1.5_vz-1.5_w2_d0.3 | D4: 24 | E4: 0.11515798 | F4: 0.010331756 | G4: 0.24143768 | H4: 0.0285625
A5: H-L | B5: two_adjacent | C5: h3_vz0_w6_d0.11 | D5: 24 | E5: -0.17358605 | F5: -0.43004072 | G5: 0.14193006 | H5: 0.065166667
A6: I-H | B6: one_out | C6: h1.5_vz-1.5_w2_d0.3 | D6: 24 | E6: 0.16002573 | F6: -0.63734265 | G6: 0.7495851 | H6: -0.0054791667
A7: I-H | B7: one_out | C7: h3_vz0_w6_d0.11 | D7: 24 | E7: -0.087073995 | F7: -3.2903984 | G7: 2.8092897 | H7: 0.027145833
A8: I-H | B8: two_adjacent | C8: h1.5_vz-1.5_w2_d0.3 | D8: 24 | E8: -0.025966148 | F8: -0.19318146 | G8: 0.096328962 | H8: 0.000625
A9: I-H | B9: two_adjacent | C9: h3_vz0_w6_d0.11 | D9: 24 | E9: -0.0094449705 | F9: -0.15050655 | G9: 0.12054117 | H9: 0.0048125
A10: I-L | B10: one_out | C10: h1.5_vz-1.5_w2_d0.3 | D10: 24 | E10: 0.2137898 | F10: -0.52874947 | G10: 1.1876589 | H10: 0.0354375
A11: I-L | B11: one_out | C11: h3_vz0_w6_d0.11 | D11: 24 | E11: -0.38396594 | F11: -3.6925433 | G11: 1.2630865 | H11: 0.069479167
A12: I-L | B12: two_adjacent | C12: h1.5_vz-1.5_w2_d0.3 | D12: 24 | E12: 0.089191834 | F12: -0.14580902 | G12: 0.25753059 | H12: 0.0291875
A13: I-L | B13: two_adjacent | C13: h3_vz0_w6_d0.11 | D13: 24 | E13: -0.18303103 | F13: -0.39185548 | G13: 0.025087771 | H13: 0.069979167

Sheet Convergence
A1: class | B1: cell | C1: trial | D1: impact_speed_dt5e-4 | E1: impact_speed_dt2.5e-4 | F1: impact_tilt_rad_dt5e-4 | G1: impact_tilt_rad_dt2.5e-4 | H1: speed_delta | I1: landed_agrees
A2: one_out | B2: h3_vz0_w6_d0.11 | C2: 0 | D2: 7.3686958 | E2: 7.364343 | F2: 1.081137 | G2: 1.0777597 | H2: 0.0043528248 | I2: TRUE
A3: one_out | B3: h3_vz0_w6_d0.11 | C3: 1 | D3: 7.681894 | E3: 7.6850454 | F3: 1.3265024 | G3: 1.3220976 | H3: 0.0031513778 | I3: TRUE
A4: one_out | B4: h3_vz0_w6_d0.11 | C4: 2 | D4: 7.7638328 | E4: 7.76673 | F4: 1.4884582 | G4: 1.4940764 | H4: 0.0028971841 | I4: TRUE
A5: one_out | B5: h1.5_vz-1.5_w2_d0.3 | C5: 0 | D5: 5.1673964 | E5: 5.1669857 | F5: 1.2480047 | G5: 1.2483568 | H5: 0.00041071535 | I5: TRUE
A6: one_out | B6: h1.5_vz-1.5_w2_d0.3 | C6: 1 | D6: 4.8018392 | E6: 4.8021455 | F6: 1.0596707 | G6: 1.0601796 | H6: 0.00030627303 | I6: TRUE
A7: one_out | B7: h1.5_vz-1.5_w2_d0.3 | C7: 2 | D7: 4.8736807 | E7: 4.8743827 | F7: 1.154657 | G7: 1.155028 | H7: 0.00070191448 | I7: TRUE
A8: partial_authority | B8: h3_vz0_w6_d0.11 | C8: 0 | D8: 0.98970585 | E8: 0.98972598 | F8: 0.069270373 | G8: 0.068704148 | H8: 2.0129764e-05 | I8: TRUE
A9: partial_authority | B9: h3_vz0_w6_d0.11 | C9: 1 | D9: 0.98899679 | E9: 0.98895585 | F9: 0.021154467 | G9: 0.02162794 | H9: 4.0941656e-05 | I9: TRUE
A10: partial_authority | B10: h3_vz0_w6_d0.11 | C10: 2 | D10: 0.9914055 | E10: 0.99135474 | F10: 0.06288969 | G10: 0.061979313 | H10: 5.0757824e-05 | I10: TRUE
A11: partial_authority | B11: h1.5_vz-1.5_w2_d0.3 | C11: 0 | D11: 5.1473539 | E11: 5.1464778 | F11: 1.1845288 | G11: 1.1839817 | H11: 0.00087613519 | I11: TRUE
A12: partial_authority | B12: h1.5_vz-1.5_w2_d0.3 | C12: 1 | D12: 4.7344414 | E12: 4.7330678 | F12: 0.89277743 | G12: 0.89362822 | H12: 0.0013736742 | I12: TRUE
A13: partial_authority | B13: h1.5_vz-1.5_w2_d0.3 | C13: 2 | D13: 4.7690708 | E13: 4.7689353 | F13: 0.95587716 | G13: 0.95563822 | H13: 0.00013552869 | I13: TRUE

Sheet Paired A
A1: class | B1: cell | C1: a | D1: b | E1: n | F1: both_safe | G1: only_a | H1: only_b | I1: neither | J1: discordant | K1: delta | L1: pi_lower | M1: pi_upper | N1: midp | O1: verdict
A2: one_out | B2: h1.5_vz-1.5_w2_d0.11 | C2: mechanism | D2: realloc_only | E2: 30 | F2: 2 | G2: 0 | H2: 0 | I2: 28 | J2: 0 | K2: 0 | N2: 1 | O2: no_discordant_pairs
A3: one_out | B3: h1.5_vz-1.5_w2_d0.3 | C3: mechanism | D3: realloc_only | E3: 300 | F3: 0 | G3: 0 | H3: 0 | I3: 300 | J3: 0 | K3: 0 | N3: 1 | O3: no_discordant_pairs
A4: one_out | B4: h1.5_vz-1.5_w6_d0.11 | C4: mechanism | D4: realloc_only | E4: 30 | F4: 0 | G4: 0 | H4: 0 | I4: 30 | J4: 0 | K4: 0 | N4: 1 | O4: no_discordant_pairs
A5: one_out | B5: h1.5_vz-1.5_w6_d0.3 | C5: mechanism | D5: realloc_only | E5: 30 | F5: 0 | G5: 0 | H5: 0 | I5: 30 | J5: 0 | K5: 0 | N5: 1 | O5: no_discordant_pairs
A6: one_out | B6: h1.5_vz0_w2_d0.11 | C6: mechanism | D6: realloc_only | E6: 30 | F6: 10 | G6: 0 | H6: 1 | I6: 19 | J6: 1 | K6: -0.033333333 | L6: 0 | M6: 0.975 | N6: 0.5 | O6: not_distinguished
A7: one_out | B7: h1.5_vz0_w2_d0.3 | C7: mechanism | D7: realloc_only | E7: 30 | F7: 0 | G7: 0 | H7: 0 | I7: 30 | J7: 0 | K7: 0 | N7: 1 | O7: no_discordant_pairs
A8: one_out | B8: h1.5_vz0_w6_d0.11 | C8: mechanism | D8: realloc_only | E8: 30 | F8: 0 | G8: 0 | H8: 0 | I8: 30 | J8: 0 | K8: 0 | N8: 1 | O8: no_discordant_pairs
A9: one_out | B9: h1.5_vz0_w6_d0.3 | C9: mechanism | D9: realloc_only | E9: 30 | F9: 0 | G9: 0 | H9: 0 | I9: 30 | J9: 0 | K9: 0 | N9: 1 | O9: no_discordant_pairs
A10: one_out | B10: h3_vz-1.5_w2_d0.11 | C10: mechanism | D10: realloc_only | E10: 30 | F10: 6 | G10: 0 | H10: 3 | I10: 21 | J10: 3 | K10: -0.1 | L10: 0 | M10: 0.70759823 | N10: 0.125 | O10: not_distinguished
A11: one_out | B11: h3_vz-1.5_w2_d0.3 | C11: mechanism | D11: realloc_only | E11: 30 | F11: 0 | G11: 0 | H11: 0 | I11: 30 | J11: 0 | K11: 0 | N11: 1 | O11: no_discordant_pairs
A12: one_out | B12: h3_vz-1.5_w6_d0.11 | C12: mechanism | D12: realloc_only | E12: 30 | F12: 0 | G12: 0 | H12: 0 | I12: 30 | J12: 0 | K12: 0 | N12: 1 | O12: no_discordant_pairs
A13: one_out | B13: h3_vz-1.5_w6_d0.3 | C13: mechanism | D13: realloc_only | E13: 30 | F13: 0 | G13: 0 | H13: 0 | I13: 30 | J13: 0 | K13: 0 | N13: 1 | O13: no_discordant_pairs
A14: one_out | B14: h3_vz0_w2_d0.11 | C14: mechanism | D14: realloc_only | E14: 30 | F14: 9 | G14: 0 | H14: 2 | I14: 19 | J14: 2 | K14: -0.066666667 | L14: 0 | M14: 0.84188612 | N14: 0.25 | O14: not_distinguished
A15: one_out | B15: h3_vz0_w2_d0.3 | C15: mechanism | D15: realloc_only | E15: 30 | F15: 3 | G15: 0 | H15: 4 | I15: 23 | J15: 4 | K15: -0.13333333 | L15: 0 | M15: 0.60236464 | N15: 0.0625 | O15: not_distinguished
A16: one_out | B16: h3_vz0_w6_d0.11 | C16: mechanism | D16: realloc_only | E16: 300 | F16: 0 | G16: 0 | H16: 0 | I16: 300 | J16: 0 | K16: 0 | N16: 1 | O16: no_discordant_pairs
A17: one_out | B17: h3_vz0_w6_d0.3 | C17: mechanism | D17: realloc_only | E17: 30 | F17: 0 | G17: 0 | H17: 0 | I17: 30 | J17: 0 | K17: 0 | N17: 1 | O17: no_discordant_pairs
A18: one_out | B18: h6_vz-1.5_w2_d0.11 | C18: mechanism | D18: realloc_only | E18: 30 | F18: 11 | G18: 0 | H18: 4 | I18: 15 | J18: 4 | K18: -0.13333333 | L18: 0 | M18: 0.60236464 | N18: 0.0625 | O18: not_distinguished
A19: one_out | B19: h6_vz-1.5_w2_d0.3 | C19: mechanism | D19: realloc_only | E19: 30 | F19: 11 | G19: 0 | H19: 5 | I19: 14 | J19: 5 | K19: -0.16666667 | L19: 0 | M19: 0.52182375 | N19: 0.03125 | O19: not_distinguished
A20: one_out | B20: h6_vz-1.5_w6_d0.11 | C20: mechanism | D20: realloc_only | E20: 30 | F20: 0 | G20: 0 | H20: 0 | I20: 30 | J20: 0 | K20: 0 | N20: 1 | O20: no_discordant_pairs
A21: one_out | B21: h6_vz-1.5_w6_d0.3 | C21: mechanism | D21: realloc_only | E21: 30 | F21: 0 | G21: 0 | H21: 0 | I21: 30 | J21: 0 | K21: 0 | N21: 1 | O21: no_discordant_pairs
A22: one_out | B22: h6_vz0_w2_d0.11 | C22: mechanism | D22: realloc_only | E22: 30 | F22: 14 | G22: 0 | H22: 1 | I22: 15 | J22: 1 | K22: -0.033333333 | L22: 0 | M22: 0.975 | N22: 0.5 | O22: not_distinguished
A23: one_out | B23: h6_vz0_w2_d0.3 | C23: mechanism | D23: realloc_only | E23: 30 | F23: 10 | G23: 0 | H23: 3 | I23: 17 | J23: 3 | K23: -0.1 | L23: 0 | M23: 0.70759823 | N23: 0.125 | O23: not_distinguished
A24: one_out | B24: h6_vz0_w6_d0.11 | C24: mechanism | D24: realloc_only | E24: 30 | F24: 0 | G24: 0 | H24: 0 | I24: 30 | J24: 0 | K24: 0 | N24: 1 | O24: no_discordant_pairs
A25: one_out | B25: h6_vz0_w6_d0.3 | C25: mechanism | D25: realloc_only | E25: 30 | F25: 0 | G25: 0 | H25: 1 | I25: 29 | J25: 1 | K25: -0.033333333 | L25: 0 | M25: 0.975 | N25: 0.5 | O25: not_distinguished
A26: partial_authority | B26: h1.5_vz-1.5_w2_d0.11 | C26: mechanism | D26: realloc_only | E26: 30 | F26: 29 | G26: 0 | H26: 1 | I26: 0 | J26: 1 | K26: -0.033333333 | L26: 0 | M26: 0.975 | N26: 0.5 | O26: not_distinguished
A27: partial_authority | B27: h1.5_vz-1.5_w2_d0.3 | C27: mechanism | D27: realloc_only | E27: 30 | F27: 0 | G27: 0 | H27: 0 | I27: 30 | J27: 0 | K27: 0 | N27: 1 | O27: no_discordant_pairs
A28: partial_authority | B28: h1.5_vz-1.5_w6_d0.11 | C28: mechanism | D28: realloc_only | E28: 30 | F28: 0 | G28: 0 | H28: 4 | I28: 26 | J28: 4 | K28: -0.13333333 | L28: 0 | M28: 0.60236464 | N28: 0.0625 | O28: not_distinguished
A29: partial_authority | B29: h1.5_vz-1.5_w6_d0.3 | C29: mechanism | D29: realloc_only | E29: 30 | F29: 0 | G29: 0 | H29: 0 | I29: 30 | J29: 0 | K29: 0 | N29: 1 | O29: no_discordant_pairs
A30: partial_authority | B30: h1.5_vz0_w2_d0.11 | C30: mechanism | D30: realloc_only | E30: 30 | F30: 30 | G30: 0 | H30: 0 | I30: 0 | J30: 0 | K30: 0 | N30: 1 | O30: no_discordant_pairs
A31: partial_authority | B31: h1.5_vz0_w2_d0.3 | C31: mechanism | D31: realloc_only | E31: 30 | F31: 5 | G31: 0 | H31: 3 | I31: 22 | J31: 3 | K31: -0.1 | L31: 0 | M31: 0.70759823 | N31: 0.125 | O31: not_distinguished
A32: partial_authority | B32: h1.5_vz0_w6_d0.11 | C32: mechanism | D32: realloc_only | E32: 30 | F32: 14 | G32: 1 | H32: 3 | I32: 12 | J32: 4 | K32: -0.066666667 | L32: 0.0063094632 | M32: 0.80587955 | N32: 0.375 | O32: not_distinguished
A33: partial_authority | B33: h1.5_vz0_w6_d0.3 | C33: mechanism | D33: realloc_only | E33: 30 | F33: 0 | G33: 0 | H33: 0 | I33: 30 | J33: 0 | K33: 0 | N33: 1 | O33: no_discordant_pairs
A34: partial_authority | B34: h3_vz-1.5_w2_d0.11 | C34: mechanism | D34: realloc_only | E34: 30 | F34: 30 | G34: 0 | H34: 0 | I34: 0 | J34: 0 | K34: 0 | N34: 1 | O34: no_discordant_pairs
A35: partial_authority | B35: h3_vz-1.5_w2_d0.3 | C35: mechanism | D35: realloc_only | E35: 30 | F35: 8 | G35: 0 | H35: 6 | I35: 16 | J35: 6 | K35: -0.2 | L35: 0 | M35: 0.45925813 | N35: 0.015625 | O35: b_superior
A36: partial_authority | B36: h3_vz-1.5_w6_d0.11 | C36: mechanism | D36: realloc_only | E36: 30 | F36: 16 | G36: 1 | H36: 7 | I36: 6 | J36: 8 | K36: -0.2 | L36: 0.0031597235 | M36: 0.52650967 | N36: 0.0390625 | O36: not_distinguished
A37: partial_authority | B37: h3_vz-1.5_w6_d0.3 | C37: mechanism | D37: realloc_only | E37: 30 | F37: 0 | G37: 0 | H37: 0 | I37: 30 | J37: 0 | K37: 0 | N37: 1 | O37: no_discordant_pairs
A38: partial_authority | B38: h3_vz0_w2_d0.11 | C38: mechanism | D38: realloc_only | E38: 30 | F38: 30 | G38: 0 | H38: 0 | I38: 0 | J38: 0 | K38: 0 | N38: 1 | O38: no_discordant_pairs
A39: partial_authority | B39: h3_vz0_w2_d0.3 | C39: mechanism | D39: realloc_only | E39: 30 | F39: 28 | G39: 0 | H39: 2 | I39: 0 | J39: 2 | K39: -0.066666667 | L39: 0 | M39: 0.84188612 | N39: 0.25 | O39: not_distinguished
A40: partial_authority | B40: h3_vz0_w6_d0.11 | C40: mechanism | D40: realloc_only | E40: 30 | F40: 30 | G40: 0 | H40: 0 | I40: 0 | J40: 0 | K40: 0 | N40: 1 | O40: no_discordant_pairs
...

Sheet Paired A2
A1: class | B1: cell | C1: a | D1: b | E1: n | F1: both_safe | G1: only_a | H1: only_b | I1: neither | J1: discordant | K1: delta | L1: pi_lower | M1: pi_upper | N1: midp | O1: verdict
A2: one_out | B2: h1.5_vz-1.5_w2_d0.11 | C2: mechanism | D2: realloc_only | E2: 30 | F2: 2 | G2: 0 | H2: 0 | I2: 28 | J2: 0 | K2: 0 | N2: 1 | O2: no_discordant_pairs
A3: one_out | B3: h1.5_vz-1.5_w2_d0.3 | C3: mechanism | D3: realloc_only | E3: 300 | F3: 0 | G3: 0 | H3: 0 | I3: 300 | J3: 0 | K3: 0 | N3: 1 | O3: no_discordant_pairs
A4: one_out | B4: h1.5_vz-1.5_w6_d0.11 | C4: mechanism | D4: realloc_only | E4: 30 | F4: 0 | G4: 0 | H4: 0 | I4: 30 | J4: 0 | K4: 0 | N4: 1 | O4: no_discordant_pairs
A5: one_out | B5: h1.5_vz-1.5_w6_d0.3 | C5: mechanism | D5: realloc_only | E5: 30 | F5: 0 | G5: 0 | H5: 0 | I5: 30 | J5: 0 | K5: 0 | N5: 1 | O5: no_discordant_pairs
A6: one_out | B6: h1.5_vz0_w2_d0.11 | C6: mechanism | D6: realloc_only | E6: 30 | F6: 10 | G6: 0 | H6: 1 | I6: 19 | J6: 1 | K6: -0.033333333 | L6: 0 | M6: 0.975 | N6: 0.5 | O6: not_distinguished
A7: one_out | B7: h1.5_vz0_w2_d0.3 | C7: mechanism | D7: realloc_only | E7: 30 | F7: 0 | G7: 0 | H7: 0 | I7: 30 | J7: 0 | K7: 0 | N7: 1 | O7: no_discordant_pairs
A8: one_out | B8: h1.5_vz0_w6_d0.11 | C8: mechanism | D8: realloc_only | E8: 30 | F8: 0 | G8: 0 | H8: 0 | I8: 30 | J8: 0 | K8: 0 | N8: 1 | O8: no_discordant_pairs
A9: one_out | B9: h1.5_vz0_w6_d0.3 | C9: mechanism | D9: realloc_only | E9: 30 | F9: 0 | G9: 0 | H9: 0 | I9: 30 | J9: 0 | K9: 0 | N9: 1 | O9: no_discordant_pairs
A10: one_out | B10: h3_vz-1.5_w2_d0.11 | C10: mechanism | D10: realloc_only | E10: 30 | F10: 6 | G10: 0 | H10: 3 | I10: 21 | J10: 3 | K10: -0.1 | L10: 0 | M10: 0.70759823 | N10: 0.125 | O10: not_distinguished
A11: one_out | B11: h3_vz-1.5_w2_d0.3 | C11: mechanism | D11: realloc_only | E11: 30 | F11: 0 | G11: 0 | H11: 0 | I11: 30 | J11: 0 | K11: 0 | N11: 1 | O11: no_discordant_pairs
A12: one_out | B12: h3_vz-1.5_w6_d0.11 | C12: mechanism | D12: realloc_only | E12: 30 | F12: 0 | G12: 0 | H12: 0 | I12: 30 | J12: 0 | K12: 0 | N12: 1 | O12: no_discordant_pairs
A13: one_out | B13: h3_vz-1.5_w6_d0.3 | C13: mechanism | D13: realloc_only | E13: 30 | F13: 0 | G13: 0 | H13: 0 | I13: 30 | J13: 0 | K13: 0 | N13: 1 | O13: no_discordant_pairs
A14: one_out | B14: h3_vz0_w2_d0.11 | C14: mechanism | D14: realloc_only | E14: 30 | F14: 9 | G14: 0 | H14: 1 | I14: 20 | J14: 1 | K14: -0.033333333 | L14: 0 | M14: 0.975 | N14: 0.5 | O14: not_distinguished
A15: one_out | B15: h3_vz0_w2_d0.3 | C15: mechanism | D15: realloc_only | E15: 30 | F15: 3 | G15: 0 | H15: 4 | I15: 23 | J15: 4 | K15: -0.13333333 | L15: 0 | M15: 0.60236464 | N15: 0.0625 | O15: not_distinguished
A16: one_out | B16: h3_vz0_w6_d0.11 | C16: mechanism | D16: realloc_only | E16: 300 | F16: 0 | G16: 0 | H16: 0 | I16: 300 | J16: 0 | K16: 0 | N16: 1 | O16: no_discordant_pairs
A17: one_out | B17: h3_vz0_w6_d0.3 | C17: mechanism | D17: realloc_only | E17: 30 | F17: 0 | G17: 0 | H17: 0 | I17: 30 | J17: 0 | K17: 0 | N17: 1 | O17: no_discordant_pairs
A18: one_out | B18: h6_vz-1.5_w2_d0.11 | C18: mechanism | D18: realloc_only | E18: 30 | F18: 11 | G18: 0 | H18: 4 | I18: 15 | J18: 4 | K18: -0.13333333 | L18: 0 | M18: 0.60236464 | N18: 0.0625 | O18: not_distinguished
A19: one_out | B19: h6_vz-1.5_w2_d0.3 | C19: mechanism | D19: realloc_only | E19: 30 | F19: 11 | G19: 0 | H19: 5 | I19: 14 | J19: 5 | K19: -0.16666667 | L19: 0 | M19: 0.52182375 | N19: 0.03125 | O19: not_distinguished
A20: one_out | B20: h6_vz-1.5_w6_d0.11 | C20: mechanism | D20: realloc_only | E20: 30 | F20: 0 | G20: 0 | H20: 0 | I20: 30 | J20: 0 | K20: 0 | N20: 1 | O20: no_discordant_pairs
A21: one_out | B21: h6_vz-1.5_w6_d0.3 | C21: mechanism | D21: realloc_only | E21: 30 | F21: 0 | G21: 0 | H21: 0 | I21: 30 | J21: 0 | K21: 0 | N21: 1 | O21: no_discordant_pairs
A22: one_out | B22: h6_vz0_w2_d0.11 | C22: mechanism | D22: realloc_only | E22: 30 | F22: 14 | G22: 0 | H22: 1 | I22: 15 | J22: 1 | K22: -0.033333333 | L22: 0 | M22: 0.975 | N22: 0.5 | O22: not_distinguished
A23: one_out | B23: h6_vz0_w2_d0.3 | C23: mechanism | D23: realloc_only | E23: 30 | F23: 10 | G23: 0 | H23: 3 | I23: 17 | J23: 3 | K23: -0.1 | L23: 0 | M23: 0.70759823 | N23: 0.125 | O23: not_distinguished
A24: one_out | B24: h6_vz0_w6_d0.11 | C24: mechanism | D24: realloc_only | E24: 30 | F24: 0 | G24: 0 | H24: 0 | I24: 30 | J24: 0 | K24: 0 | N24: 1 | O24: no_discordant_pairs
A25: one_out | B25: h6_vz0_w6_d0.3 | C25: mechanism | D25: realloc_only | E25: 30 | F25: 0 | G25: 0 | H25: 1 | I25: 29 | J25: 1 | K25: -0.033333333 | L25: 0 | M25: 0.975 | N25: 0.5 | O25: not_distinguished
A26: partial_authority | B26: h1.5_vz-1.5_w2_d0.11 | C26: mechanism | D26: realloc_only | E26: 30 | F26: 29 | G26: 0 | H26: 1 | I26: 0 | J26: 1 | K26: -0.033333333 | L26: 0 | M26: 0.975 | N26: 0.5 | O26: not_distinguished
A27: partial_authority | B27: h1.5_vz-1.5_w2_d0.3 | C27: mechanism | D27: realloc_only | E27: 30 | F27: 0 | G27: 0 | H27: 0 | I27: 30 | J27: 0 | K27: 0 | N27: 1 | O27: no_discordant_pairs
A28: partial_authority | B28: h1.5_vz-1.5_w6_d0.11 | C28: mechanism | D28: realloc_only | E28: 30 | F28: 0 | G28: 0 | H28: 4 | I28: 26 | J28: 4 | K28: -0.13333333 | L28: 0 | M28: 0.60236464 | N28: 0.0625 | O28: not_distinguished
